<?xml version="1.0" encoding="utf-8"?>
<!-- This URDF was automatically created by SolidWorks to URDF Exporter! Originally created by Stephen Brawner (brawner@gmail.com) 
     Commit Version: 1.6.0-4-g7f85cfe  Build Version: 1.6.7995.38578
     For more information, please see http://wiki.ros.org/sw_urdf_exporter -->
<robot
  name="a2_v1_0_0">
  <link
    name="base_link">
    <inertial>
      <origin
        xyz="0.0029629 0.035495 -2.2759E-05"
        rpy="0 0 0" />
      <mass
        value="1.3" />
      <inertia
        ixx="0.00099446"
        ixy="7.4794E-06"
        ixz="-3.8739E-08"
        iyy="0.0013348"
        iyz="4.0506E-07"
        izz="0.00098199" />
    </inertial>
    <visual>
      <origin
        xyz="0 0 0"
        rpy="0 0 0" />
      <geometry>
        <mesh
          filename="package://a2_v1_0_0/meshes/base_link.STL" />
      </geometry>
      <material
        name="">
        <color
          rgba="0.82353 0.82353 1 1" />
      </material>
    </visual>
    <collision>
      <origin
        xyz="0 0 0"
        rpy="0 0 0" />
      <geometry>
        <mesh
          filename="package://a2_v1_0_0/meshes/base_link.STL" />
      </geometry>
    </collision>
  </link>
  <link
    name="left_arm_link1">
    <inertial>
      <origin
        xyz="5.6143E-05 0.099162 -1.1142E-07"
        rpy="0 0 0" />
      <mass
        value="1.147" />
      <inertia
        ixx="0.0008567"
        ixy="-3.0552E-07"
        ixz="-4.1251E-10"
        iyy="0.00036852"
        iyz="2.7816E-10"
        izz="0.00068069" />
    </inertial>
    <visual>
      <origin
        xyz="0 0 0"
        rpy="0 0 0" />
      <geometry>
        <mesh
          filename="package://a2_v1_0_0/meshes/left_arm_link1.STL" />
      </geometry>
      <material
        name="">
        <color
          rgba="0.79216 0.81961 0.93333 1" />
      </material>
    </visual>
    <collision>
      <origin
        xyz="0 0 0"
        rpy="0 0 0" />
      <geometry>
        <mesh
          filename="package://a2_v1_0_0/meshes/left_arm_link1.STL" />
      </geometry>
    </collision>
  </link>
  <joint
    name="left_arm_joint1"
    type="revolute">
    <origin
      xyz="0.0026402 0.04025 -4.1013E-05"
      rpy="0 0 0" />
    <parent
      link="base_link" />
    <child
      link="left_arm_link1" />
    <axis
      xyz="0 1 0" />
    <limit
      lower="-2.879795"
      upper="2.879795"
      effort="0"
      velocity="0" />
  </joint>
  <link
    name="left_arm_link2">
    <inertial>
      <origin
        xyz="-0.003777 6.0912E-08 -0.079023"
        rpy="0 0 0" />
      <mass
        value="0.987" />
      <inertia
        ixx="0.00066126"
        ixy="-4.9922E-09"
        ixz="0.00010525"
        iyy="0.0007196"
        iyz="-1.1931E-09"
        izz="0.00067895" />
    </inertial>
    <visual>
      <origin
        xyz="0 0 0"
        rpy="0 0 0" />
      <geometry>
        <mesh
          filename="package://a2_v1_0_0/meshes/left_arm_link2.STL" />
      </geometry>
      <material
        name="">
        <color
          rgba="0.82353 0.82353 1 1" />
      </material>
    </visual>
    <collision>
      <origin
        xyz="0 0 0"
        rpy="0 0 0" />
      <geometry>
        <mesh
          filename="package://a2_v1_0_0/meshes/left_arm_link2.STL" />
      </geometry>
    </collision>
  </link>
  <joint
    name="left_arm_joint2"
    type="revolute">
    <origin
      xyz="0.0005121 0.11252 0"
      rpy="0 0 0" />
    <parent
      link="left_arm_link1" />
    <child
      link="left_arm_link2" />
    <axis
      xyz="1 0 0" />
    <limit
      lower="-3.1416"
      upper="1.57"
      effort="0"
      velocity="0" />
  </joint>
  <link
    name="left_arm_link3">
    <inertial>
      <origin
        xyz="-4.852E-05 0.00012394 -0.14794"
        rpy="0 0 0" />
      <mass
        value="0.92" />
      <inertia
        ixx="0.0036544"
        ixy="1.3714E-06"
        ixz="-2.6892E-06"
        iyy="0.0036341"
        iyz="6.7878E-06"
        izz="0.00045576" />
    </inertial>
    <visual>
      <origin
        xyz="0 0 0"
        rpy="0 0 0" />
      <geometry>
        <mesh
          filename="package://a2_v1_0_0/meshes/left_arm_link3.STL" />
      </geometry>
      <material
        name="">
        <color
          rgba="0.82353 0.82353 1 1" />
      </material>
    </visual>
    <collision>
      <origin
        xyz="0 0 0"
        rpy="0 0 0" />
      <geometry>
        <mesh
          filename="package://a2_v1_0_0/meshes/left_arm_link3.STL" />
      </geometry>
    </collision>
  </link>
  <joint
    name="left_arm_joint3"
    type="revolute">
    <origin
      xyz="-0.0005121 0 -0.084469"
      rpy="0 0 0" />
    <parent
      link="left_arm_link2" />
    <child
      link="left_arm_link3" />
    <axis
      xyz="0 0 1" />
    <limit
      lower="-2.356196"
      upper="2.356196"
      effort="0"
      velocity="0" />
  </joint>
  <link
    name="left_arm_link4">
    <inertial>
      <origin
        xyz="-2.663E-05 0.00059393 -0.072164"
        rpy="0 0 0" />
      <mass
        value="0.63" />
      <inertia
        ixx="0.00034073"
        ixy="-3.6455E-07"
        ixz="4.0522E-07"
        iyy="0.0003057"
        iyz="1.4631E-07"
        izz="0.00020271" />
    </inertial>
    <visual>
      <origin
        xyz="0 0 0"
        rpy="0 0 0" />
      <geometry>
        <mesh
          filename="package://a2_v1_0_0/meshes/left_arm_link4.STL" />
      </geometry>
      <material
        name="">
        <color
          rgba="0.79216 0.81961 0.93333 1" />
      </material>
    </visual>
    <collision>
      <origin
        xyz="0 0 0"
        rpy="0 0 0" />
      <geometry>
        <mesh
          filename="package://a2_v1_0_0/meshes/left_arm_link4.STL" />
      </geometry>
    </collision>
  </link>
  <joint
    name="left_arm_joint4"
    type="revolute">
    <origin
      xyz="0 0.000315 -0.22553"
      rpy="0 0 0" />
    <parent
      link="left_arm_link3" />
    <child
      link="left_arm_link4" />
    <axis
      xyz="0 1 0" />
    <limit
      lower="-2.617995"
      upper="0.523599"
      effort="0"
      velocity="0" />
  </joint>
  <link
    name="left_arm_link5">
    <inertial>
      <origin
        xyz="-6.1767E-08 -0.0028892 -0.10239"
        rpy="0 0 0" />
      <mass
        value="0.63" />
      <inertia
        ixx="0.00059963"
        ixy="-2.0797E-09"
        ixz="-4.002E-10"
        iyy="0.0006094"
        iyz="-4.714E-05"
        izz="0.0002532" />
    </inertial>
    <visual>
      <origin
        xyz="0 0 0"
        rpy="0 0 0" />
      <geometry>
        <mesh
          filename="package://a2_v1_0_0/meshes/left_arm_link5.STL" />
      </geometry>
      <material
        name="">
        <color
          rgba="0.79216 0.81961 0.93333 1" />
      </material>
    </visual>
    <collision>
      <origin
        xyz="0 0 0"
        rpy="0 0 0" />
      <geometry>
        <mesh
          filename="package://a2_v1_0_0/meshes/left_arm_link5.STL" />
      </geometry>
    </collision>
  </link>
  <joint
    name="left_arm_joint5"
    type="revolute">
    <origin
      xyz="0 -0.000315 -0.06775"
      rpy="0 0 0" />
    <parent
      link="left_arm_link4" />
    <child
      link="left_arm_link5" />
    <axis
      xyz="0 0 1" />
    <limit
      lower="-2.356196"
      upper="2.356196"
      effort="0"
      velocity="0" />
  </joint>
  <link
    name="left_arm_link6">
    <inertial>
      <origin
        xyz="-0.00060694 -0.00078314 0.00013867"
        rpy="0 0 0" />
      <mass
        value="0.63" />
      <inertia
        ixx="8.068E-05"
        ixy="8.1397E-08"
        ixz="-7.7673E-07"
        iyy="8.5569E-05"
        iyz="-1.8603E-08"
        izz="9.8434E-05" />
    </inertial>
    <visual>
      <origin
        xyz="0 0 0"
        rpy="0 0 0" />
      <geometry>
        <mesh
          filename="package://a2_v1_0_0/meshes/left_arm_link6.STL" />
      </geometry>
      <material
        name="">
        <color
          rgba="0.79216 0.81961 0.93333 1" />
      </material>
    </visual>
    <collision>
      <origin
        xyz="0 0 0"
        rpy="0 0 0" />
      <geometry>
        <mesh
          filename="package://a2_v1_0_0/meshes/left_arm_link6.STL" />
      </geometry>
    </collision>
  </link>
  <joint
    name="left_arm_joint6"
    type="revolute">
    <origin
      xyz="0 0 -0.19025"
      rpy="0 0 0" />
    <parent
      link="left_arm_link5" />
    <child
      link="left_arm_link6" />
    <axis
      xyz="0 1 0" />
    <limit
      lower="-1.047198"
      upper="1.047198"
      effort="0"
      velocity="0" />
  </joint>
  <link
    name="left_arm_link7">
    <inertial>
      <origin
        xyz="0.016889 1.1814E-07 -0.031417"
        rpy="0 0 0" />
      <mass
        value="0.2" />
      <inertia
        ixx="1.8488E-05"
        ixy="8.5283E-11"
        ixz="-8.7538E-06"
        iyy="2.583E-05"
        iyz="-3.5672E-10"
        izz="1.5392E-05" />
    </inertial>
    <visual>
      <origin
        xyz="0 0 0"
        rpy="0 0 0" />
      <geometry>
        <mesh
          filename="package://a2_v1_0_0/meshes/left_arm_link7.STL" />
      </geometry>
      <material
        name="">
        <color
          rgba="0.89804 0.91765 0.92941 1" />
      </material>
    </visual>
    <collision>
      <origin
        xyz="0 0 0"
        rpy="0 0 0" />
      <geometry>
        <mesh
          filename="package://a2_v1_0_0/meshes/left_arm_link7.STL" />
      </geometry>
    </collision>
  </link>
  <joint
    name="left_arm_joint7"
    type="revolute">
    <origin
      xyz="0 0 0"
      rpy="0 0 0" />
    <parent
      link="left_arm_link6" />
    <child
      link="left_arm_link7" />
    <axis
      xyz="1 0 0" />
    <limit
      lower="-1.570797"
      upper="1.570797"
      effort="0"
      velocity="0" />
  </joint>
</robot>
