<?xml version="1.0" encoding="utf-8"?>
<!-- This URDF was automatically created by SolidWorks to URDF Exporter! Originally created by Stephen Brawner (brawner@gmail.com) 
     Commit Version: 1.6.0-4-g7f85cfe  Build Version: 1.6.7995.38578
     For more information, please see http://wiki.ros.org/sw_urdf_exporter -->
<robot
  name="r1_v2_1_0">
  <link
    name="left_arm_base_link">
    <inertial>
      <origin
        xyz="-0.0005634 0.038934 3.1874E-06"
        rpy="0 0 0" />
      <mass
        value="1.658" />
      <inertia
        ixx="0.0010597"
        ixy="1.9821E-05"
        ixz="-1.6752E-07"
        iyy="0.0011787"
        iyz="-1.9146E-07"
        izz="0.0010647" />
    </inertial>
    <visual>
      <origin
        xyz="0 0 0"
        rpy="0 0 0" />
      <geometry>
        <mesh
          filename="package://mobiman/urdf/R1/meshes/left_arm_base_link.STL" />
      </geometry>
      <material
        name="">
        <color
          rgba="0.79216 0.81961 0.93333 1" />
      </material>
    </visual>
    <collision>
      <origin
        xyz="0 0 0"
        rpy="0 0 0" />
      <geometry>
        <mesh
          filename="package://mobiman/urdf/R1/meshes/left_arm_base_link.STL" />
      </geometry>
    </collision>
  </link>
  <link
    name="left_arm_link1">
    <inertial>
      <origin
        xyz="0.000015 0.105259 -0.001954"
        rpy="0 0 0" />
      <mass
        value="1.164" />
      <inertia
        ixx="0.001125"
        ixy="0.0"
        ixz="0.0"
        iyy="0.001084"
        iyz="-0.000023"
        izz="0.001158" />
    </inertial>
    <visual>
      <origin
        xyz="0 0 0"
        rpy="0 0 0" />
      <geometry>
        <mesh
          filename="package://mobiman/urdf/R1/meshes/left_arm_link1.STL" />
      </geometry>
      <material
        name="">
        <color
          rgba="0.79216 0.81961 0.93333 1" />
      </material>
    </visual>
    <collision>
      <origin
        xyz="0 0 0"
        rpy="0 0 0" />
      <geometry>
        <mesh
          filename="package://mobiman/urdf/R1/meshes/left_arm_link1.STL" />
      </geometry>
    </collision>
  </link>
  <joint
    name="left_arm_joint1"
    type="revolute">
    <origin
      xyz="-0.0011149 0.0446 0"
      rpy="0 0 0" />
    <parent
      link="left_arm_base_link" />
    <child
      link="left_arm_link1" />
    <axis
      xyz="0 1 0" />
    <limit
      lower="-2.8798"
      upper="2.8798"
      effort="40"
      velocity="20.944" />
  </joint>
  <link
    name="left_arm_link2">
    <inertial>
      <origin
        xyz="-0.23622 0.016352 -0.00013275"
        rpy="0 0 0" />
      <mass
        value="1.3" />
      <inertia
        ixx="0.00060638"
        ixy="0.00041817"
        ixz="0.00014956"
        iyy="0.0075936"
        iyz="-8.0916E-06"
        izz="0.0075712" />
    </inertial>
    <visual>
      <origin
        xyz="0 0 0"
        rpy="0 0 0" />
      <geometry>
        <mesh
          filename="package://mobiman/urdf/R1/meshes/left_arm_link2.STL" />
      </geometry>
      <material
        name="">
        <color
          rgba="0.79216 0.81961 0.93333 1" />
      </material>
    </visual>
    <collision>
      <origin
        xyz="0 0 0"
        rpy="0 0 0" />
      <geometry>
        <mesh
          filename="package://mobiman/urdf/R1/meshes/left_arm_link2.STL" />
      </geometry>
    </collision>
  </link>
  <joint
    name="left_arm_joint2"
    type="revolute">
    <origin
      xyz="0 0.1061 0"
      rpy="0 0 0" />
    <parent
      link="left_arm_link1" />
    <child
      link="left_arm_link2" />
    <axis
      xyz="0 0 -1" />
    <limit
      lower="0"
      upper="3.2289"
      effort="40"
      velocity="20.944" />
  </joint>
  <link
    name="left_arm_link3">
    <inertial>
      <origin
        xyz="0.045114 0.054616 -0.00045593"
        rpy="0 0 0" />
      <mass
        value="0.818" />
      <inertia
        ixx="0.00060107"
        ixy="-0.00022467"
        ixz="-7.1194E-06"
        iyy="0.0013959"
        iyz="-9.7503E-06"
        izz="0.0015027" />
    </inertial>
    <visual>
      <origin
        xyz="0 0 0"
        rpy="0 0 0" />
      <geometry>
        <mesh
          filename="package://mobiman/urdf/R1/meshes/left_arm_link3.STL" />
      </geometry>
      <material
        name="">
        <color
          rgba="0.79216 0.81961 0.93333 1" />
      </material>
    </visual>
    <collision>
      <origin
        xyz="0 0 0"
        rpy="0 0 0" />
      <geometry>
        <mesh
          filename="package://mobiman/urdf/R1/meshes/left_arm_link3.STL" />
      </geometry>
    </collision>
  </link>
  <joint
    name="left_arm_joint3"
    type="revolute">
    <origin
      xyz="-0.34928 0.019998 0"
      rpy="0 0 0" />
    <parent
      link="left_arm_link2" />
    <child
      link="left_arm_link3" />
    <axis
      xyz="0 0 -1" />
    <limit
      lower="-3.3161"
      upper="0"
      effort="27"
      velocity="7.5398" />
  </joint>
  <link
    name="left_arm_link4">
    <inertial>
      <origin
        xyz="0.24285 0.0023784 1.279E-06"
        rpy="0 0 0" />
      <mass
        value="0.698" />
      <inertia
        ixx="8.45E-05"
        ixy="-8.2627E-07"
        ixz="-2.2607E-09"
        iyy="0.00010174"
        iyz="5.3612E-09"
        izz="9.7044E-05" />
    </inertial>
    <visual>
      <origin
        xyz="0 0 0"
        rpy="0 0 0" />
      <geometry>
        <mesh
          filename="package://mobiman/urdf/R1/meshes/left_arm_link4.STL" />
      </geometry>
      <material
        name="">
        <color
          rgba="1 1 1 1" />
      </material>
    </visual>
    <collision>
      <origin
        xyz="0 0 0"
        rpy="0 0 0" />
      <geometry>
        <mesh
          filename="package://mobiman/urdf/R1/meshes/left_arm_link4.STL" />
      </geometry>
    </collision>
  </link>
  <joint
    name="left_arm_joint4"
    type="revolute">
    <origin
      xyz="0.02735 0.069767 0"
      rpy="0 0 0" />
    <parent
      link="left_arm_link3" />
    <child
      link="left_arm_link4" />
    <axis
      xyz="1 0 0" />
    <limit
      lower="-2.8798"
      upper="2.8798"
      effort="7"
      velocity="25.133" />
  </joint>
  <link
    name="left_arm_link5">
    <inertial>
      <origin
        xyz="0.054309 0.0041811 4.0699E-06"
        rpy="0 0 0" />
      <mass
        value="0.417" />
      <inertia
        ixx="8.3999E-05"
        ixy="1.6234E-05"
        ixz="7.4127E-08"
        iyy="9.8498E-05"
        iyz="-1.3811E-08"
        izz="0.00011333" />
    </inertial>
    <visual>
      <origin
        xyz="0 0 0"
        rpy="0 0 0" />
      <geometry>
        <mesh
          filename="package://mobiman/urdf/R1/meshes/left_arm_link5.STL" />
      </geometry>
      <material
        name="">
        <color
          rgba="1 1 1 1" />
      </material>
    </visual>
    <collision>
      <origin
        xyz="0 0 0"
        rpy="0 0 0" />
      <geometry>
        <mesh
          filename="package://mobiman/urdf/R1/meshes/left_arm_link5.STL" />
      </geometry>
    </collision>
  </link>
  <joint
    name="left_arm_joint5"
    type="revolute">
    <origin
      xyz="0.2463 -0.00049894 0"
      rpy="0 0 0" />
    <parent
      link="left_arm_link4" />
    <child
      link="left_arm_link5" />
    <axis
      xyz="0 1 0" />
    <limit
      lower="-1.6581"
      upper="1.6581"
      effort="7"
      velocity="25.133" />
  </joint>
  <link
    name="left_arm_link6">
    <inertial>
      <origin
        xyz="0.028138 1.2134E-07 5.4049E-08"
        rpy="0 0 0" />
      <mass
        value="0.037" />
      <inertia
        ixx="3.5662E-06"
        ixy="6.6514E-12"
        ixz="2.9628E-12"
        iyy="2.0238E-06"
        iyz="-4.1666E-12"
        izz="2.0238E-06" />
    </inertial>
    <visual>
      <origin
        xyz="0 0 0"
        rpy="0 0 0" />
      <geometry>
        <mesh
          filename="package://mobiman/urdf/R1/meshes/left_arm_link6.STL" />
      </geometry>
      <material
        name="">
        <color
          rgba="0.82353 0.82353 1 1" />
      </material>
    </visual>
    <collision>
      <origin
        xyz="0 0 0"
        rpy="0 0 0" />
      <geometry>
        <mesh
          filename="package://mobiman/urdf/R1/meshes/left_arm_link6.STL" />
      </geometry>
    </collision>
  </link>
  <joint
    name="left_arm_joint6"
    type="revolute">
    <origin
      xyz="0.058249 0.00050025 0"
      rpy="0 0 0" />
    <parent
      link="left_arm_link5" />
    <child
      link="left_arm_link6" />
    <axis
      xyz="1 0 0" />
    <limit
      lower="-2.8798"
      upper="2.8798"
      effort="7"
      velocity="25.133" />
  </joint>
  <link
    name="left_realsense_link">
    <inertial>
      <origin
        xyz="0.022169 0.0060171 -0.017353"
        rpy="0 0 0" />
      <mass
        value="0.175" />
      <inertia
        ixx="6.965E-06"
        ixy="2.6612E-06"
        ixz="1.2797E-06"
        iyy="2.3281E-05"
        iyz="-1.4268E-06"
        izz="2.5513E-05" />
    </inertial>
    <visual>
      <origin
        xyz="0 0 0"
        rpy="0 0 0" />
      <geometry>
        <mesh
          filename="package://mobiman/urdf/R1/meshes/left_realsense_link.STL" />
      </geometry>
      <material
        name="">
        <color
          rgba="0.8 0.8 0.8 1" />
      </material>
    </visual>
    <collision>
      <origin
        xyz="0 0 0"
        rpy="0 0 0" />
      <geometry>
        <mesh
          filename="package://mobiman/urdf/R1/meshes/left_realsense_link.STL" />
      </geometry>
    </collision>
  </link>
  <joint
    name="left_realsense_joint"
    type="fixed">
    <origin
      xyz="0.098768 0.0021071 0.05055"
      rpy="-2.0071 0.0077831 -1.5708" />
    <parent
      link="left_arm_link6" />
    <child
      link="left_realsense_link" />
    <axis
      xyz="0 0 0" />
  </joint>
  <link
    name="left_gripper_link">
    <inertial>
      <origin
        xyz="-0.031107 -1.3893E-07 -1.437E-07"
        rpy="0 0 0" />
      <mass
        value="0.604" />
      <inertia
        ixx="0.00017588"
        ixy="4.1789E-10"
        ixz="-5.3493E-10"
        iyy="9.8637E-05"
        iyz="-8.1856E-08"
        izz="0.00016512" />
    </inertial>
    <visual>
      <origin
        xyz="0 0 0"
        rpy="0 0 0" />
      <geometry>
        <mesh
          filename="package://mobiman/urdf/R1/meshes/left_gripper_link.STL" />
      </geometry>
      <material
        name="">
        <color
          rgba="0.82353 0.82353 1 1" />
      </material>
    </visual>
    <collision>
      <origin
        xyz="0 0 0"
        rpy="0 0 0" />
      <geometry>
        <mesh
          filename="package://mobiman/urdf/R1/meshes/left_gripper_link.STL" />
      </geometry>
    </collision>
  </link>
  <joint
    name="left_gripper_joint"
    type="fixed">
    <origin
      xyz="0.1039 0 0"
      rpy="0 0 0" />
    <parent
      link="left_arm_link6" />
    <child
      link="left_gripper_link" />
    <axis
      xyz="0 0 0" />
  </joint>
  <link
    name="left_gripper_finger_link1">
    <inertial>
      <origin
        xyz="-0.019589 -0.015114 0.0054225"
        rpy="0 0 0" />
      <mass
        value="0.027" />
      <inertia
        ixx="2.4057E-06"
        ixy="3.9897E-07"
        ixz="5.1206E-08"
        iyy="5.7108E-06"
        iyz="6.1948E-08"
        izz="6.4849E-06" />
    </inertial>
    <visual>
      <origin
        xyz="0 0 0"
        rpy="0 0 0" />
      <geometry>
        <mesh
          filename="package://mobiman/urdf/R1/meshes/left_gripper_finger_link1.STL" />
      </geometry>
      <material
        name="">
        <color
          rgba="0.82353 0.82353 1 1" />
      </material>
    </visual>
    <collision>
      <origin
        xyz="0 0 0"
        rpy="0 0 0" />
      <geometry>
        <mesh
          filename="package://mobiman/urdf/R1/meshes/left_gripper_finger_link1.STL" />
      </geometry>
    </collision>
  </link>
  <joint
    name="left_gripper_finger_joint1"
    type="prismatic">
    <origin
      xyz="0.03689 0.013453 0.00012067"
      rpy="0 0 0" />
    <parent
      link="left_gripper_link" />
    <child
      link="left_gripper_finger_link1" />
    <axis
      xyz="0 1 0" />
    <limit
      lower="0"
      upper="0.05"
      effort="100"
      velocity="0.25" />
  </joint>
  <link
    name="left_gripper_finger_link2">
    <inertial>
      <origin
        xyz="-0.01959 0.015114 -0.0054226"
        rpy="0 0 0" />
      <mass
        value="0.027" />
      <inertia
        ixx="2.4057E-06"
        ixy="-3.99E-07"
        ixz="-5.1222E-08"
        iyy="5.7108E-06"
        iyz="6.1946E-08"
        izz="6.4849E-06" />
    </inertial>
    <visual>
      <origin
        xyz="0 0 0"
        rpy="0 0 0" />
      <geometry>
        <mesh
          filename="package://mobiman/urdf/R1/meshes/left_gripper_finger_link2.STL" />
      </geometry>
      <material
        name="">
        <color
          rgba="0.82353 0.82353 1 1" />
      </material>
    </visual>
    <collision>
      <origin
        xyz="0 0 0"
        rpy="0 0 0" />
      <geometry>
        <mesh
          filename="package://mobiman/urdf/R1/meshes/left_gripper_finger_link2.STL" />
      </geometry>
    </collision>
  </link>
  <joint
    name="left_gripper_finger_joint2"
    type="prismatic">
    <origin
      xyz="0.03689 -0.013453 -0.00012053"
      rpy="0 0 0" />
    <parent
      link="left_gripper_link" />
    <child
      link="left_gripper_finger_link2" />
    <axis
      xyz="0 -1 0" />
    <limit
      lower="0"
      upper="0.05"
      effort="100"
      velocity="0.25" />
  </joint>
</robot>